2018-12-22 16:11:29,841 [HttpRunnerManager:56] [views:login] [INFO]- qianliguang 登录成功
2018-12-22 16:30:38,557 [django.request:118] [exception:handle_uncaught_exception] [ERROR]- Internal Server Error: /api/run_batch_test_dubbo/
Traceback (most recent call last):
  File "C:\Python36\lib\site-packages\django\core\handlers\exception.py", line 35, in inner
    response = get_response(request)
  File "C:\Python36\lib\site-packages\django\core\handlers\base.py", line 139, in _get_response
    "returned None instead." % (callback.__module__, view_name)
ValueError: The view HttpRunnerManager.activator.process didn't return an HttpResponse object. It returned None instead.
2018-12-22 17:33:06,212 [django.request:118] [exception:handle_uncaught_exception] [ERROR]- Internal Server Error: /api/run_test_dubbo/
Traceback (most recent call last):
  File "C:\Python36\lib\site-packages\django\core\handlers\exception.py", line 35, in inner
    response = get_response(request)
  File "C:\Python36\lib\site-packages\django\core\handlers\base.py", line 128, in _get_response
    response = self.process_exception_by_middleware(e, request)
  File "C:\Python36\lib\site-packages\django\core\handlers\base.py", line 126, in _get_response
    response = wrapped_callback(request, *callback_args, **callback_kwargs)
  File "D:\jzs_workspace\projects\httprunnerm_test\HttpRunnerManager\activator.py", line 15, in process
    result = fun(request, index) if index else fun(request)
  File "D:\jzs_workspace\projects\httprunnerm_test\ApiManager\views.py", line 40, in wrapper
    return func(request, *args, **kwargs)
  File "D:\jzs_workspace\projects\httprunnerm_test\ApiManager\views.py", line 915, in run_test_dubbo
    obj_dict=select_case(id)
  File "D:\jzs_workspace\projects\httprunnerm_test\ApiManager\dubbo_runner.py", line 13, in select_case
    request = eval(obj.request)
AttributeError: 'QuerySet' object has no attribute 'request'
2018-12-24 14:51:08,496 [HttpRunnerManager:56] [views:login] [INFO]- qianliguang 登录成功
2018-12-24 16:49:20,468 [django.request:118] [exception:handle_uncaught_exception] [ERROR]- Internal Server Error: /api/run_test_dubbo/
Traceback (most recent call last):
  File "C:\Python36\lib\site-packages\django\core\handlers\exception.py", line 35, in inner
    response = get_response(request)
  File "C:\Python36\lib\site-packages\django\core\handlers\base.py", line 128, in _get_response
    response = self.process_exception_by_middleware(e, request)
  File "C:\Python36\lib\site-packages\django\core\handlers\base.py", line 126, in _get_response
    response = wrapped_callback(request, *callback_args, **callback_kwargs)
  File "D:\jzs_workspace\projects\httprunnerm_test\HttpRunnerManager\activator.py", line 15, in process
    result = fun(request, index) if index else fun(request)
  File "D:\jzs_workspace\projects\httprunnerm_test\ApiManager\views.py", line 40, in wrapper
    return func(request, *args, **kwargs)
  File "D:\jzs_workspace\projects\httprunnerm_test\ApiManager\views.py", line 916, in run_test_dubbo
    url=obj_dict.get('url')
AttributeError: 'list' object has no attribute 'get'
2018-12-24 16:50:25,332 [django.request:118] [exception:handle_uncaught_exception] [ERROR]- Internal Server Error: /api/run_test_dubbo/
Traceback (most recent call last):
  File "C:\Python36\lib\site-packages\django\core\handlers\exception.py", line 35, in inner
    response = get_response(request)
  File "C:\Python36\lib\site-packages\django\core\handlers\base.py", line 128, in _get_response
    response = self.process_exception_by_middleware(e, request)
  File "C:\Python36\lib\site-packages\django\core\handlers\base.py", line 126, in _get_response
    response = wrapped_callback(request, *callback_args, **callback_kwargs)
  File "D:\jzs_workspace\projects\httprunnerm_test\HttpRunnerManager\activator.py", line 15, in process
    result = fun(request, index) if index else fun(request)
  File "D:\jzs_workspace\projects\httprunnerm_test\ApiManager\views.py", line 40, in wrapper
    return func(request, *args, **kwargs)
  File "D:\jzs_workspace\projects\httprunnerm_test\ApiManager\views.py", line 916, in run_test_dubbo
    obj_dict=obj_list[0]
IndexError: list index out of range
2018-12-24 16:51:30,407 [django.request:118] [exception:handle_uncaught_exception] [ERROR]- Internal Server Error: /api/run_test_dubbo/
Traceback (most recent call last):
  File "C:\Python36\lib\site-packages\django\core\handlers\exception.py", line 35, in inner
    response = get_response(request)
  File "C:\Python36\lib\site-packages\django\core\handlers\base.py", line 128, in _get_response
    response = self.process_exception_by_middleware(e, request)
  File "C:\Python36\lib\site-packages\django\core\handlers\base.py", line 126, in _get_response
    response = wrapped_callback(request, *callback_args, **callback_kwargs)
  File "D:\jzs_workspace\projects\httprunnerm_test\HttpRunnerManager\activator.py", line 15, in process
    result = fun(request, index) if index else fun(request)
  File "D:\jzs_workspace\projects\httprunnerm_test\ApiManager\views.py", line 40, in wrapper
    return func(request, *args, **kwargs)
  File "D:\jzs_workspace\projects\httprunnerm_test\ApiManager\views.py", line 916, in run_test_dubbo
    obj_dict=obj_list[0]
IndexError: list index out of range
2018-12-24 16:53:17,394 [django.request:118] [exception:handle_uncaught_exception] [ERROR]- Internal Server Error: /api/run_test_dubbo/
Traceback (most recent call last):
  File "C:\Python36\lib\site-packages\django\core\handlers\exception.py", line 35, in inner
    response = get_response(request)
  File "C:\Python36\lib\site-packages\django\core\handlers\base.py", line 128, in _get_response
    response = self.process_exception_by_middleware(e, request)
  File "C:\Python36\lib\site-packages\django\core\handlers\base.py", line 126, in _get_response
    response = wrapped_callback(request, *callback_args, **callback_kwargs)
  File "D:\jzs_workspace\projects\httprunnerm_test\HttpRunnerManager\activator.py", line 15, in process
    result = fun(request, index) if index else fun(request)
  File "D:\jzs_workspace\projects\httprunnerm_test\ApiManager\views.py", line 40, in wrapper
    return func(request, *args, **kwargs)
  File "D:\jzs_workspace\projects\httprunnerm_test\ApiManager\views.py", line 916, in run_test_dubbo
    obj_dict=obj_list[0]
IndexError: list index out of range
2018-12-24 17:13:59,575 [django.request:118] [exception:handle_uncaught_exception] [ERROR]- Internal Server Error: /api/run_test_dubbo/
Traceback (most recent call last):
  File "C:\Python36\lib\site-packages\django\core\handlers\exception.py", line 35, in inner
    response = get_response(request)
  File "C:\Python36\lib\site-packages\django\core\handlers\base.py", line 128, in _get_response
    response = self.process_exception_by_middleware(e, request)
  File "C:\Python36\lib\site-packages\django\core\handlers\base.py", line 126, in _get_response
    response = wrapped_callback(request, *callback_args, **callback_kwargs)
  File "D:\jzs_workspace\projects\httprunnerm_test\HttpRunnerManager\activator.py", line 15, in process
    result = fun(request, index) if index else fun(request)
  File "D:\jzs_workspace\projects\httprunnerm_test\ApiManager\views.py", line 40, in wrapper
    return func(request, *args, **kwargs)
  File "D:\jzs_workspace\projects\httprunnerm_test\ApiManager\views.py", line 931, in run_test_dubbo
    request,response,passnum,failnum=DR.invoke(interface,method,name,validate,params)
ValueError: not enough values to unpack (expected 4, got 2)
2018-12-24 17:30:07,138 [django.request:118] [exception:handle_uncaught_exception] [ERROR]- Internal Server Error: /api/run_test_dubbo/
Traceback (most recent call last):
  File "C:\Python36\lib\site-packages\django\core\handlers\exception.py", line 35, in inner
    response = get_response(request)
  File "C:\Python36\lib\site-packages\django\core\handlers\base.py", line 128, in _get_response
    response = self.process_exception_by_middleware(e, request)
  File "C:\Python36\lib\site-packages\django\core\handlers\base.py", line 126, in _get_response
    response = wrapped_callback(request, *callback_args, **callback_kwargs)
  File "D:\jzs_workspace\projects\httprunnerm_test\HttpRunnerManager\activator.py", line 15, in process
    result = fun(request, index) if index else fun(request)
  File "D:\jzs_workspace\projects\httprunnerm_test\ApiManager\views.py", line 40, in wrapper
    return func(request, *args, **kwargs)
  File "D:\jzs_workspace\projects\httprunnerm_test\ApiManager\views.py", line 933, in run_test_dubbo
    resultData=DR.summary(obj_list=obj_list,Dubbo_request=request.split('str->list'),
AttributeError: 'dict' object has no attribute 'split'
2018-12-24 17:32:48,269 [django.request:118] [exception:handle_uncaught_exception] [ERROR]- Internal Server Error: /api/run_test_dubbo/
Traceback (most recent call last):
  File "C:\Python36\lib\site-packages\django\core\handlers\exception.py", line 35, in inner
    response = get_response(request)
  File "C:\Python36\lib\site-packages\django\core\handlers\base.py", line 128, in _get_response
    response = self.process_exception_by_middleware(e, request)
  File "C:\Python36\lib\site-packages\django\core\handlers\base.py", line 126, in _get_response
    response = wrapped_callback(request, *callback_args, **callback_kwargs)
  File "D:\jzs_workspace\projects\httprunnerm_test\HttpRunnerManager\activator.py", line 15, in process
    result = fun(request, index) if index else fun(request)
  File "D:\jzs_workspace\projects\httprunnerm_test\ApiManager\views.py", line 40, in wrapper
    return func(request, *args, **kwargs)
  File "D:\jzs_workspace\projects\httprunnerm_test\ApiManager\views.py", line 934, in run_test_dubbo
    Dubbo_response=response.split('str->list'),spendTime=spendTime.split('str->list'))
AttributeError: 'dict' object has no attribute 'split'
2018-12-25 11:30:35,261 [HttpRunnerManager:56] [views:login] [INFO]- qianliguang 登录成功
2018-12-25 11:35:23,881 [django.request:118] [exception:handle_uncaught_exception] [ERROR]- Internal Server Error: /api/run_batch_test_dubbo/
Traceback (most recent call last):
  File "C:\Python36\lib\site-packages\django\core\handlers\exception.py", line 35, in inner
    response = get_response(request)
  File "C:\Python36\lib\site-packages\django\core\handlers\base.py", line 128, in _get_response
    response = self.process_exception_by_middleware(e, request)
  File "C:\Python36\lib\site-packages\django\core\handlers\base.py", line 126, in _get_response
    response = wrapped_callback(request, *callback_args, **callback_kwargs)
  File "D:\jzs_workspace\projects\httprunnerm_test\HttpRunnerManager\activator.py", line 15, in process
    result = fun(request, index) if index else fun(request)
  File "D:\jzs_workspace\projects\httprunnerm_test\ApiManager\views.py", line 40, in wrapper
    return func(request, *args, **kwargs)
  File "D:\jzs_workspace\projects\httprunnerm_test\ApiManager\views.py", line 947, in run_batch_test_dubbo
    from ApiManager.dubbo_runner import dubboRunner,select_case,get_case_id
  File "D:\jzs_workspace\projects\httprunnerm_test\ApiManager\dubbo_runner.py", line 81
    global passnum,status
    ^
SyntaxError: name 'status' is used prior to global declaration
2018-12-25 11:47:34,399 [HttpRunnerManager:56] [views:login] [INFO]- qianliguang 登录成功
2018-12-25 11:51:59,321 [django.request:118] [exception:handle_uncaught_exception] [ERROR]- Internal Server Error: /api/run_batch_test_dubbo/
Traceback (most recent call last):
  File "C:\Python36\lib\site-packages\django\core\handlers\exception.py", line 35, in inner
    response = get_response(request)
  File "C:\Python36\lib\site-packages\django\core\handlers\base.py", line 128, in _get_response
    response = self.process_exception_by_middleware(e, request)
  File "C:\Python36\lib\site-packages\django\core\handlers\base.py", line 126, in _get_response
    response = wrapped_callback(request, *callback_args, **callback_kwargs)
  File "D:\jzs_workspace\projects\httprunnerm_test\HttpRunnerManager\activator.py", line 15, in process
    result = fun(request, index) if index else fun(request)
  File "D:\jzs_workspace\projects\httprunnerm_test\ApiManager\views.py", line 40, in wrapper
    return func(request, *args, **kwargs)
  File "D:\jzs_workspace\projects\httprunnerm_test\ApiManager\views.py", line 976, in run_batch_test_dubbo
    resultData=DR.summary(obj_list=obj_list,Dubbo_request=request_ls,Dubbo_response=response_ls,spendTime=spendTime_ls)
  File "D:\jzs_workspace\projects\httprunnerm_test\ApiManager\dubbo_runner.py", line 98, in summary
    "totalTime": self.sum_time(spendTime), "testSkip": 0}
  File "D:\jzs_workspace\projects\httprunnerm_test\ApiManager\dubbo_runner.py", line 130, in sum_time
    s+=index
TypeError: unsupported operand type(s) for +=: 'int' and 'str'
2018-12-25 13:45:26,306 [HttpRunnerManager:154] [operation:add_case_data] [INFO]- 第三个dubbo用例添加成功: {'test': {'request': {'url': '10.1.27.221:20880', 'method': 'querySettleReconBillByPage', 'DubboInterface': 'com.dfire.fin.account.service.ISettleBillService', 'json': {'billDateBegin': '20181118', 'billDateEnd': '20181207', 'accountNo': '385449654759834896', 'brhId': 'C_385449654759834895', 'accountType': '008'}}, 'name': '第三个dubbo', 'validate': [{'comparator': 'equals', 'check': "'success': True", 'expected': 'content'}]}}
2018-12-25 13:45:33,536 [django.request:118] [exception:handle_uncaught_exception] [ERROR]- Internal Server Error: /api/run_test_dubbo/
Traceback (most recent call last):
  File "C:\Python36\lib\site-packages\django\core\handlers\exception.py", line 35, in inner
    response = get_response(request)
  File "C:\Python36\lib\site-packages\django\core\handlers\base.py", line 128, in _get_response
    response = self.process_exception_by_middleware(e, request)
  File "C:\Python36\lib\site-packages\django\core\handlers\base.py", line 126, in _get_response
    response = wrapped_callback(request, *callback_args, **callback_kwargs)
  File "D:\jzs_workspace\projects\httprunnerm_test\HttpRunnerManager\activator.py", line 15, in process
    result = fun(request, index) if index else fun(request)
  File "D:\jzs_workspace\projects\httprunnerm_test\ApiManager\views.py", line 40, in wrapper
    return func(request, *args, **kwargs)
  File "D:\jzs_workspace\projects\httprunnerm_test\ApiManager\views.py", line 936, in run_test_dubbo
    Dubbo_response=response_ls,spendTime=spendTime.split('str->list'))
  File "D:\jzs_workspace\projects\httprunnerm_test\ApiManager\dubbo_runner.py", line 98, in summary
    "totalTime": self.sum_time(spendTime), "testSkip": 0}
  File "D:\jzs_workspace\projects\httprunnerm_test\ApiManager\dubbo_runner.py", line 130, in sum_time
    s+=index
TypeError: unsupported operand type(s) for +=: 'int' and 'str'
2018-12-25 13:57:43,467 [django.request:118] [exception:handle_uncaught_exception] [ERROR]- Internal Server Error: /api/run_batch_test_dubbo/
Traceback (most recent call last):
  File "C:\Python36\lib\site-packages\django\core\handlers\exception.py", line 35, in inner
    response = get_response(request)
  File "C:\Python36\lib\site-packages\django\core\handlers\base.py", line 128, in _get_response
    response = self.process_exception_by_middleware(e, request)
  File "C:\Python36\lib\site-packages\django\core\handlers\base.py", line 126, in _get_response
    response = wrapped_callback(request, *callback_args, **callback_kwargs)
  File "D:\jzs_workspace\projects\httprunnerm_test\HttpRunnerManager\activator.py", line 15, in process
    result = fun(request, index) if index else fun(request)
  File "D:\jzs_workspace\projects\httprunnerm_test\ApiManager\views.py", line 40, in wrapper
    return func(request, *args, **kwargs)
  File "D:\jzs_workspace\projects\httprunnerm_test\ApiManager\views.py", line 976, in run_batch_test_dubbo
    resultData=DR.summary(obj_list=obj_list,Dubbo_request=request_ls,Dubbo_response=response_ls,spendTime=spendTime_ls)
  File "D:\jzs_workspace\projects\httprunnerm_test\ApiManager\dubbo_runner.py", line 110, in summary
    self._del()
  File "D:\jzs_workspace\projects\httprunnerm_test\ApiManager\dubbo_runner.py", line 135, in _del
    del(failnum,passnum,status)
UnboundLocalError: local variable 'failnum' referenced before assignment
2018-12-25 13:58:59,308 [django.request:118] [exception:handle_uncaught_exception] [ERROR]- Internal Server Error: /api/run_batch_test_dubbo/
Traceback (most recent call last):
  File "C:\Python36\lib\site-packages\django\core\handlers\exception.py", line 35, in inner
    response = get_response(request)
  File "C:\Python36\lib\site-packages\django\core\handlers\base.py", line 128, in _get_response
    response = self.process_exception_by_middleware(e, request)
  File "C:\Python36\lib\site-packages\django\core\handlers\base.py", line 126, in _get_response
    response = wrapped_callback(request, *callback_args, **callback_kwargs)
  File "D:\jzs_workspace\projects\httprunnerm_test\HttpRunnerManager\activator.py", line 15, in process
    result = fun(request, index) if index else fun(request)
  File "D:\jzs_workspace\projects\httprunnerm_test\ApiManager\views.py", line 40, in wrapper
    return func(request, *args, **kwargs)
  File "D:\jzs_workspace\projects\httprunnerm_test\ApiManager\views.py", line 976, in run_batch_test_dubbo
    resultData=DR.summary(obj_list=obj_list,Dubbo_request=request_ls,Dubbo_response=response_ls,spendTime=spendTime_ls)
  File "D:\jzs_workspace\projects\httprunnerm_test\ApiManager\dubbo_runner.py", line 110, in summary
    self._del()
  File "D:\jzs_workspace\projects\httprunnerm_test\ApiManager\dubbo_runner.py", line 135, in _del
    del failnum,passnum,status
UnboundLocalError: local variable 'failnum' referenced before assignment
2018-12-25 13:59:59,622 [django.request:118] [exception:handle_uncaught_exception] [ERROR]- Internal Server Error: /api/run_batch_test_dubbo/
Traceback (most recent call last):
  File "C:\Python36\lib\site-packages\django\core\handlers\exception.py", line 35, in inner
    response = get_response(request)
  File "C:\Python36\lib\site-packages\django\core\handlers\base.py", line 128, in _get_response
    response = self.process_exception_by_middleware(e, request)
  File "C:\Python36\lib\site-packages\django\core\handlers\base.py", line 126, in _get_response
    response = wrapped_callback(request, *callback_args, **callback_kwargs)
  File "D:\jzs_workspace\projects\httprunnerm_test\HttpRunnerManager\activator.py", line 15, in process
    result = fun(request, index) if index else fun(request)
  File "D:\jzs_workspace\projects\httprunnerm_test\ApiManager\views.py", line 40, in wrapper
    return func(request, *args, **kwargs)
  File "D:\jzs_workspace\projects\httprunnerm_test\ApiManager\views.py", line 976, in run_batch_test_dubbo
    resultData=DR.summary(obj_list=obj_list,Dubbo_request=request_ls,Dubbo_response=response_ls,spendTime=spendTime_ls)
  File "D:\jzs_workspace\projects\httprunnerm_test\ApiManager\dubbo_runner.py", line 110, in summary
    self._del()
  File "D:\jzs_workspace\projects\httprunnerm_test\ApiManager\dubbo_runner.py", line 135, in _del
    del failnum
UnboundLocalError: local variable 'failnum' referenced before assignment
2018-12-25 14:00:38,365 [django.request:118] [exception:handle_uncaught_exception] [ERROR]- Internal Server Error: /api/run_batch_test_dubbo/
Traceback (most recent call last):
  File "C:\Python36\lib\site-packages\django\core\handlers\exception.py", line 35, in inner
    response = get_response(request)
  File "C:\Python36\lib\site-packages\django\core\handlers\base.py", line 128, in _get_response
    response = self.process_exception_by_middleware(e, request)
  File "C:\Python36\lib\site-packages\django\core\handlers\base.py", line 126, in _get_response
    response = wrapped_callback(request, *callback_args, **callback_kwargs)
  File "D:\jzs_workspace\projects\httprunnerm_test\HttpRunnerManager\activator.py", line 15, in process
    result = fun(request, index) if index else fun(request)
  File "D:\jzs_workspace\projects\httprunnerm_test\ApiManager\views.py", line 40, in wrapper
    return func(request, *args, **kwargs)
  File "D:\jzs_workspace\projects\httprunnerm_test\ApiManager\views.py", line 976, in run_batch_test_dubbo
    resultData=DR.summary(obj_list=obj_list,Dubbo_request=request_ls,Dubbo_response=response_ls,spendTime=spendTime_ls)
  File "D:\jzs_workspace\projects\httprunnerm_test\ApiManager\dubbo_runner.py", line 110, in summary
    self._del()
  File "D:\jzs_workspace\projects\httprunnerm_test\ApiManager\dubbo_runner.py", line 135, in _del
    del (failnum)
UnboundLocalError: local variable 'failnum' referenced before assignment
2018-12-25 14:06:50,239 [django.request:118] [exception:handle_uncaught_exception] [ERROR]- Internal Server Error: /api/run_batch_test_dubbo/
Traceback (most recent call last):
  File "C:\Python36\lib\site-packages\django\core\handlers\exception.py", line 35, in inner
    response = get_response(request)
  File "C:\Python36\lib\site-packages\django\core\handlers\base.py", line 128, in _get_response
    response = self.process_exception_by_middleware(e, request)
  File "C:\Python36\lib\site-packages\django\core\handlers\base.py", line 126, in _get_response
    response = wrapped_callback(request, *callback_args, **callback_kwargs)
  File "D:\jzs_workspace\projects\httprunnerm_test\HttpRunnerManager\activator.py", line 15, in process
    result = fun(request, index) if index else fun(request)
  File "D:\jzs_workspace\projects\httprunnerm_test\ApiManager\views.py", line 40, in wrapper
    return func(request, *args, **kwargs)
  File "D:\jzs_workspace\projects\httprunnerm_test\ApiManager\views.py", line 976, in run_batch_test_dubbo
    resultData=DR.summary(obj_list=obj_list,Dubbo_request=request_ls,Dubbo_response=response_ls,spendTime=spendTime_ls)
  File "D:\jzs_workspace\projects\httprunnerm_test\ApiManager\dubbo_runner.py", line 110, in summary
    self.__clear_env()
  File "D:\jzs_workspace\projects\httprunnerm_test\ApiManager\dubbo_runner.py", line 136, in __clear_env
    for key in globals().keys():
RuntimeError: dictionary changed size during iteration
2018-12-25 14:25:11,594 [django.request:118] [exception:handle_uncaught_exception] [ERROR]- Internal Server Error: /api/run_batch_test_dubbo/
Traceback (most recent call last):
  File "C:\Python36\lib\site-packages\django\core\handlers\exception.py", line 35, in inner
    response = get_response(request)
  File "C:\Python36\lib\site-packages\django\core\handlers\base.py", line 128, in _get_response
    response = self.process_exception_by_middleware(e, request)
  File "C:\Python36\lib\site-packages\django\core\handlers\base.py", line 126, in _get_response
    response = wrapped_callback(request, *callback_args, **callback_kwargs)
  File "D:\jzs_workspace\projects\httprunnerm_test\HttpRunnerManager\activator.py", line 15, in process
    result = fun(request, index) if index else fun(request)
  File "D:\jzs_workspace\projects\httprunnerm_test\ApiManager\views.py", line 40, in wrapper
    return func(request, *args, **kwargs)
  File "D:\jzs_workspace\projects\httprunnerm_test\ApiManager\views.py", line 947, in run_batch_test_dubbo
    from ApiManager.dubbo_runner import dubboRunner,select_case,get_case_id
ImportError: cannot import name 'dubboRunner'
2018-12-25 14:25:20,646 [django.request:118] [exception:handle_uncaught_exception] [ERROR]- Internal Server Error: /api/run_batch_test_dubbo/
Traceback (most recent call last):
  File "C:\Python36\lib\site-packages\django\core\handlers\exception.py", line 35, in inner
    response = get_response(request)
  File "C:\Python36\lib\site-packages\django\core\handlers\base.py", line 128, in _get_response
    response = self.process_exception_by_middleware(e, request)
  File "C:\Python36\lib\site-packages\django\core\handlers\base.py", line 126, in _get_response
    response = wrapped_callback(request, *callback_args, **callback_kwargs)
  File "D:\jzs_workspace\projects\httprunnerm_test\HttpRunnerManager\activator.py", line 15, in process
    result = fun(request, index) if index else fun(request)
  File "D:\jzs_workspace\projects\httprunnerm_test\ApiManager\views.py", line 40, in wrapper
    return func(request, *args, **kwargs)
  File "D:\jzs_workspace\projects\httprunnerm_test\ApiManager\views.py", line 947, in run_batch_test_dubbo
    from ApiManager.dubbo_runner import dubboRunner,select_case,get_case_id
ImportError: cannot import name 'dubboRunner'
2018-12-25 14:40:11,556 [django.request:118] [exception:handle_uncaught_exception] [ERROR]- Internal Server Error: /api/run_batch_test_dubbo/
Traceback (most recent call last):
  File "C:\Python36\lib\site-packages\django\core\handlers\exception.py", line 35, in inner
    response = get_response(request)
  File "C:\Python36\lib\site-packages\django\core\handlers\base.py", line 128, in _get_response
    response = self.process_exception_by_middleware(e, request)
  File "C:\Python36\lib\site-packages\django\core\handlers\base.py", line 126, in _get_response
    response = wrapped_callback(request, *callback_args, **callback_kwargs)
  File "D:\jzs_workspace\projects\httprunnerm_test\HttpRunnerManager\activator.py", line 15, in process
    result = fun(request, index) if index else fun(request)
  File "D:\jzs_workspace\projects\httprunnerm_test\ApiManager\views.py", line 40, in wrapper
    return func(request, *args, **kwargs)
  File "D:\jzs_workspace\projects\httprunnerm_test\ApiManager\views.py", line 976, in run_batch_test_dubbo
    resultData=DR.summary(obj_list=obj_list,Dubbo_request=request_ls,Dubbo_response=response_ls,spendTime=spendTime_ls)
TypeError: summary() got an unexpected keyword argument 'Dubbo_request'
2018-12-25 14:40:32,300 [django.request:118] [exception:handle_uncaught_exception] [ERROR]- Internal Server Error: /api/run_batch_test_dubbo/
Traceback (most recent call last):
  File "C:\Python36\lib\site-packages\django\core\handlers\exception.py", line 35, in inner
    response = get_response(request)
  File "C:\Python36\lib\site-packages\django\core\handlers\base.py", line 128, in _get_response
    response = self.process_exception_by_middleware(e, request)
  File "C:\Python36\lib\site-packages\django\core\handlers\base.py", line 126, in _get_response
    response = wrapped_callback(request, *callback_args, **callback_kwargs)
  File "D:\jzs_workspace\projects\httprunnerm_test\HttpRunnerManager\activator.py", line 15, in process
    result = fun(request, index) if index else fun(request)
  File "D:\jzs_workspace\projects\httprunnerm_test\ApiManager\views.py", line 40, in wrapper
    return func(request, *args, **kwargs)
  File "D:\jzs_workspace\projects\httprunnerm_test\ApiManager\views.py", line 976, in run_batch_test_dubbo
    resultData=DR.summary(obj_list=obj_list,Dubbo_request=request_ls,Dubbo_response=response_ls,spendTime=spendTime_ls)
  File "D:\jzs_workspace\projects\httprunnerm_test\ApiManager\dubbo_runner.py", line 110, in summary
    passnum.__del__
AttributeError: 'int' object has no attribute '__del__'
2018-12-25 14:41:05,915 [django.request:118] [exception:handle_uncaught_exception] [ERROR]- Internal Server Error: /api/run_batch_test_dubbo/
Traceback (most recent call last):
  File "C:\Python36\lib\site-packages\django\core\handlers\exception.py", line 35, in inner
    response = get_response(request)
  File "C:\Python36\lib\site-packages\django\core\handlers\base.py", line 128, in _get_response
    response = self.process_exception_by_middleware(e, request)
  File "C:\Python36\lib\site-packages\django\core\handlers\base.py", line 126, in _get_response
    response = wrapped_callback(request, *callback_args, **callback_kwargs)
  File "D:\jzs_workspace\projects\httprunnerm_test\HttpRunnerManager\activator.py", line 15, in process
    result = fun(request, index) if index else fun(request)
  File "D:\jzs_workspace\projects\httprunnerm_test\ApiManager\views.py", line 40, in wrapper
    return func(request, *args, **kwargs)
  File "D:\jzs_workspace\projects\httprunnerm_test\ApiManager\views.py", line 976, in run_batch_test_dubbo
    resultData=DR.summary(obj_list=obj_list,Dubbo_request=request_ls,Dubbo_response=response_ls,spendTime=spendTime_ls)
  File "D:\jzs_workspace\projects\httprunnerm_test\ApiManager\dubbo_runner.py", line 93, in summary
    summary_content = {"testPass": passnum,
UnboundLocalError: local variable 'passnum' referenced before assignment
2018-12-25 14:43:14,501 [django.request:118] [exception:handle_uncaught_exception] [ERROR]- Internal Server Error: /api/run_batch_test_dubbo/
Traceback (most recent call last):
  File "C:\Python36\lib\site-packages\django\core\handlers\exception.py", line 35, in inner
    response = get_response(request)
  File "C:\Python36\lib\site-packages\django\core\handlers\base.py", line 128, in _get_response
    response = self.process_exception_by_middleware(e, request)
  File "C:\Python36\lib\site-packages\django\core\handlers\base.py", line 126, in _get_response
    response = wrapped_callback(request, *callback_args, **callback_kwargs)
  File "D:\jzs_workspace\projects\httprunnerm_test\HttpRunnerManager\activator.py", line 15, in process
    result = fun(request, index) if index else fun(request)
  File "D:\jzs_workspace\projects\httprunnerm_test\ApiManager\views.py", line 40, in wrapper
    return func(request, *args, **kwargs)
  File "D:\jzs_workspace\projects\httprunnerm_test\ApiManager\views.py", line 976, in run_batch_test_dubbo
    resultData=DR.summary(obj_list=obj_list,Dubbo_request=request_ls,Dubbo_response=response_ls,spendTime=spendTime_ls)
  File "D:\jzs_workspace\projects\httprunnerm_test\ApiManager\dubbo_runner.py", line 93, in summary
    summary_content = {"testPass": passnum,
UnboundLocalError: local variable 'passnum' referenced before assignment
2018-12-25 15:27:24,609 [django.request:118] [exception:handle_uncaught_exception] [ERROR]- Internal Server Error: /api/run_batch_test_dubbo/
Traceback (most recent call last):
  File "C:\Python36\lib\site-packages\django\core\handlers\exception.py", line 35, in inner
    response = get_response(request)
  File "C:\Python36\lib\site-packages\django\core\handlers\base.py", line 128, in _get_response
    response = self.process_exception_by_middleware(e, request)
  File "C:\Python36\lib\site-packages\django\core\handlers\base.py", line 126, in _get_response
    response = wrapped_callback(request, *callback_args, **callback_kwargs)
  File "D:\jzs_workspace\projects\httprunnerm_test\HttpRunnerManager\activator.py", line 15, in process
    result = fun(request, index) if index else fun(request)
  File "D:\jzs_workspace\projects\httprunnerm_test\ApiManager\views.py", line 40, in wrapper
    return func(request, *args, **kwargs)
  File "D:\jzs_workspace\projects\httprunnerm_test\ApiManager\views.py", line 981, in run_batch_test_dubbo
    resultData=DR.summary(obj_list=obj_list,Dubbo_request=request_ls,Dubbo_response=response_ls,spendTime=spendTime_ls,passNum=None,failNum=None)
  File "D:\jzs_workspace\projects\httprunnerm_test\ApiManager\dubbo_runner.py", line 90, in summary
    "testAll": passNum + failNum,
TypeError: unsupported operand type(s) for +: 'NoneType' and 'NoneType'
2018-12-25 15:28:17,295 [django.request:118] [exception:handle_uncaught_exception] [ERROR]- Internal Server Error: /api/run_batch_test_dubbo/
Traceback (most recent call last):
  File "C:\Python36\lib\site-packages\django\core\handlers\exception.py", line 35, in inner
    response = get_response(request)
  File "C:\Python36\lib\site-packages\django\core\handlers\base.py", line 128, in _get_response
    response = self.process_exception_by_middleware(e, request)
  File "C:\Python36\lib\site-packages\django\core\handlers\base.py", line 126, in _get_response
    response = wrapped_callback(request, *callback_args, **callback_kwargs)
  File "D:\jzs_workspace\projects\httprunnerm_test\HttpRunnerManager\activator.py", line 15, in process
    result = fun(request, index) if index else fun(request)
  File "D:\jzs_workspace\projects\httprunnerm_test\ApiManager\views.py", line 40, in wrapper
    return func(request, *args, **kwargs)
  File "D:\jzs_workspace\projects\httprunnerm_test\ApiManager\views.py", line 981, in run_batch_test_dubbo
    resultData=DR.summary(obj_list=obj_list,Dubbo_request=request_ls,Dubbo_response=response_ls,spendTime=spendTime_ls,passNum=passNum,failNum=failNum)
  File "D:\jzs_workspace\projects\httprunnerm_test\ApiManager\dubbo_runner.py", line 101, in summary
    "status":status[index]}
TypeError: 'NoneType' object is not subscriptable
2018-12-25 15:59:43,232 [django.request:118] [exception:handle_uncaught_exception] [ERROR]- Internal Server Error: /api/run_batch_test_dubbo/
Traceback (most recent call last):
  File "C:\Python36\lib\site-packages\django\core\handlers\exception.py", line 35, in inner
    response = get_response(request)
  File "C:\Python36\lib\site-packages\django\core\handlers\base.py", line 128, in _get_response
    response = self.process_exception_by_middleware(e, request)
  File "C:\Python36\lib\site-packages\django\core\handlers\base.py", line 126, in _get_response
    response = wrapped_callback(request, *callback_args, **callback_kwargs)
  File "D:\jzs_workspace\projects\httprunnerm_test\HttpRunnerManager\activator.py", line 15, in process
    result = fun(request, index) if index else fun(request)
  File "D:\jzs_workspace\projects\httprunnerm_test\ApiManager\views.py", line 40, in wrapper
    return func(request, *args, **kwargs)
  File "D:\jzs_workspace\projects\httprunnerm_test\ApiManager\views.py", line 973, in run_batch_test_dubbo
    DR = dubboRunner(url.split(':')[0],int(url.split(':')[1]))
  File "D:\jzs_workspace\projects\httprunnerm_test\ApiManager\dubbo_runner.py", line 49, in __init__
    super().__init__(host, port)
  File "C:\Python36\lib\telnetlib.py", line 218, in __init__
    self.open(host, port, timeout)
  File "C:\Python36\lib\telnetlib.py", line 234, in open
    self.sock = socket.create_connection((host, port), timeout)
  File "C:\Python36\lib\socket.py", line 724, in create_connection
    raise err
  File "C:\Python36\lib\socket.py", line 713, in create_connection
    sock.connect(sa)
ConnectionRefusedError: [WinError 10061] 由于目标计算机积极拒绝，无法连接。
2018-12-25 16:03:52,888 [django.request:118] [exception:handle_uncaught_exception] [ERROR]- Internal Server Error: /api/run_test_dubbo/
Traceback (most recent call last):
  File "C:\Python36\lib\site-packages\django\core\handlers\exception.py", line 35, in inner
    response = get_response(request)
  File "C:\Python36\lib\site-packages\django\core\handlers\base.py", line 128, in _get_response
    response = self.process_exception_by_middleware(e, request)
  File "C:\Python36\lib\site-packages\django\core\handlers\base.py", line 126, in _get_response
    response = wrapped_callback(request, *callback_args, **callback_kwargs)
  File "D:\jzs_workspace\projects\httprunnerm_test\HttpRunnerManager\activator.py", line 15, in process
    result = fun(request, index) if index else fun(request)
  File "D:\jzs_workspace\projects\httprunnerm_test\ApiManager\views.py", line 40, in wrapper
    return func(request, *args, **kwargs)
  File "D:\jzs_workspace\projects\httprunnerm_test\ApiManager\views.py", line 940, in run_test_dubbo
    Dubbo_response=response_ls,spendTime=spendTime.split('str->list'),status=status_ls,passNum=passNum,failNum=failNum)
  File "D:\jzs_workspace\projects\httprunnerm_test\ApiManager\dubbo_runner.py", line 93, in summary
    "totalTime": self.sum_time(spendTime), "testSkip": 0}
  File "D:\jzs_workspace\projects\httprunnerm_test\ApiManager\dubbo_runner.py", line 127, in sum_time
    s+=index
TypeError: unsupported operand type(s) for +=: 'int' and 'str'
2018-12-25 16:08:29,177 [django.request:118] [exception:handle_uncaught_exception] [ERROR]- Internal Server Error: /api/run_test_dubbo/
Traceback (most recent call last):
  File "C:\Python36\lib\site-packages\django\core\handlers\exception.py", line 35, in inner
    response = get_response(request)
  File "C:\Python36\lib\site-packages\django\core\handlers\base.py", line 128, in _get_response
    response = self.process_exception_by_middleware(e, request)
  File "C:\Python36\lib\site-packages\django\core\handlers\base.py", line 126, in _get_response
    response = wrapped_callback(request, *callback_args, **callback_kwargs)
  File "D:\jzs_workspace\projects\httprunnerm_test\HttpRunnerManager\activator.py", line 15, in process
    result = fun(request, index) if index else fun(request)
  File "D:\jzs_workspace\projects\httprunnerm_test\ApiManager\views.py", line 40, in wrapper
    return func(request, *args, **kwargs)
  File "D:\jzs_workspace\projects\httprunnerm_test\ApiManager\views.py", line 940, in run_test_dubbo
    Dubbo_response=response_ls,spendTime=spendTime.split('str->list'),status=status_ls,passNum=passNum,failNum=failNum)
AttributeError: 'float' object has no attribute 'split'
2018-12-27 10:26:24,359 [HttpRunnerManager:56] [views:login] [INFO]- qianliguang 登录成功
2018-12-27 11:12:00,256 [django.request:118] [exception:handle_uncaught_exception] [ERROR]- Internal Server Error: /api/run_test_dubbo/
Traceback (most recent call last):
  File "C:\Python36\lib\site-packages\django\core\handlers\exception.py", line 35, in inner
    response = get_response(request)
  File "C:\Python36\lib\site-packages\django\core\handlers\base.py", line 128, in _get_response
    response = self.process_exception_by_middleware(e, request)
  File "C:\Python36\lib\site-packages\django\core\handlers\base.py", line 126, in _get_response
    response = wrapped_callback(request, *callback_args, **callback_kwargs)
  File "D:\jzs_workspace\projects\httprunnerm_test\HttpRunnerManager\activator.py", line 15, in process
    result = fun(request, index) if index else fun(request)
  File "D:\jzs_workspace\projects\httprunnerm_test\ApiManager\views.py", line 40, in wrapper
    return func(request, *args, **kwargs)
  File "D:\jzs_workspace\projects\httprunnerm_test\ApiManager\views.py", line 915, in run_test_dubbo
    obj_dict=obj_list[0]
IndexError: list index out of range
2018-12-27 11:15:54,385 [django.request:118] [exception:handle_uncaught_exception] [ERROR]- Internal Server Error: /api/run_batch_test_dubbo/
Traceback (most recent call last):
  File "C:\Python36\lib\site-packages\django\core\handlers\exception.py", line 35, in inner
    response = get_response(request)
  File "C:\Python36\lib\site-packages\django\core\handlers\base.py", line 128, in _get_response
    response = self.process_exception_by_middleware(e, request)
  File "C:\Python36\lib\site-packages\django\core\handlers\base.py", line 126, in _get_response
    response = wrapped_callback(request, *callback_args, **callback_kwargs)
  File "D:\jzs_workspace\projects\httprunnerm_test\HttpRunnerManager\activator.py", line 15, in process
    result = fun(request, index) if index else fun(request)
  File "D:\jzs_workspace\projects\httprunnerm_test\ApiManager\views.py", line 40, in wrapper
    return func(request, *args, **kwargs)
  File "D:\jzs_workspace\projects\httprunnerm_test\ApiManager\views.py", line 959, in run_batch_test_dubbo
    obj_list=select_case(id_list)
  File "D:\jzs_workspace\projects\httprunnerm_test\ApiManager\dubbo_runner.py", line 12, in select_case
    obj = TestCaseInfo.objects.filter(id__in=id)
  File "C:\Python36\lib\site-packages\django\db\models\manager.py", line 82, in manager_method
    return getattr(self.get_queryset(), name)(*args, **kwargs)
  File "C:\Python36\lib\site-packages\django\db\models\query.py", line 836, in filter
    return self._filter_or_exclude(False, *args, **kwargs)
  File "C:\Python36\lib\site-packages\django\db\models\query.py", line 854, in _filter_or_exclude
    clone.query.add_q(Q(*args, **kwargs))
  File "C:\Python36\lib\site-packages\django\db\models\sql\query.py", line 1253, in add_q
    clause, _ = self._add_q(q_object, self.used_aliases)
  File "C:\Python36\lib\site-packages\django\db\models\sql\query.py", line 1277, in _add_q
    split_subq=split_subq,
  File "C:\Python36\lib\site-packages\django\db\models\sql\query.py", line 1215, in build_filter
    condition = self.build_lookup(lookups, col, value)
  File "C:\Python36\lib\site-packages\django\db\models\sql\query.py", line 1085, in build_lookup
    lookup = lookup_class(lhs, rhs)
  File "C:\Python36\lib\site-packages\django\db\models\lookups.py", line 18, in __init__
    self.rhs = self.get_prep_lookup()
  File "C:\Python36\lib\site-packages\django\db\models\lookups.py", line 210, in get_prep_lookup
    rhs_value = self.lhs.output_field.get_prep_value(rhs_value)
  File "C:\Python36\lib\site-packages\django\db\models\fields\__init__.py", line 947, in get_prep_value
    return int(value)
ValueError: invalid literal for int() with base 10: 'module'
2018-12-28 15:45:11,933 [HttpRunnerManager:56] [views:login] [INFO]- qianliguang 登录成功
2019-01-02 10:36:37,368 [HttpRunnerManager:56] [views:login] [INFO]- qianliguang 登录成功
2019-01-02 14:35:06,229 [django.request:118] [exception:handle_uncaught_exception] [ERROR]- Internal Server Error: /api/run_test_dubbo_module/
Traceback (most recent call last):
  File "C:\Python36\lib\site-packages\django\core\handlers\exception.py", line 35, in inner
    response = get_response(request)
  File "C:\Python36\lib\site-packages\django\core\handlers\base.py", line 139, in _get_response
    "returned None instead." % (callback.__module__, view_name)
ValueError: The view HttpRunnerManager.activator.process didn't return an HttpResponse object. It returned None instead.
2019-01-02 14:54:21,501 [django.request:118] [exception:handle_uncaught_exception] [ERROR]- Internal Server Error: /api/run_test_dubbo_module/
Traceback (most recent call last):
  File "C:\Python36\lib\site-packages\django\core\handlers\exception.py", line 35, in inner
    response = get_response(request)
  File "C:\Python36\lib\site-packages\django\core\handlers\base.py", line 128, in _get_response
    response = self.process_exception_by_middleware(e, request)
  File "C:\Python36\lib\site-packages\django\core\handlers\base.py", line 126, in _get_response
    response = wrapped_callback(request, *callback_args, **callback_kwargs)
  File "D:\jzs_workspace\projects\httprunnerm_test\HttpRunnerManager\activator.py", line 15, in process
    result = fun(request, index) if index else fun(request)
  File "D:\jzs_workspace\projects\httprunnerm_test\ApiManager\views.py", line 40, in wrapper
    return func(request, *args, **kwargs)
  File "D:\jzs_workspace\projects\httprunnerm_test\ApiManager\views.py", line 998, in run_test_dubbo_module
    idlist=get_cases_by_module(id)
  File "D:\jzs_workspace\projects\httprunnerm_test\ApiManager\utils\operation.py", line 464, in get_cases_by_module
    ids=case_opt.get_case_id_InModule(module_id)
  File "D:\jzs_workspace\projects\httprunnerm_test\ApiManager\managers.py", line 126, in get_case_id_InModule
    return self.filter(belong_module__id=module_id).filter(type=type).id
AttributeError: 'QuerySet' object has no attribute 'id'
2019-01-02 15:23:11,452 [django.request:118] [exception:handle_uncaught_exception] [ERROR]- Internal Server Error: /api/run_test_dubbo_module/
Traceback (most recent call last):
  File "C:\Python36\lib\site-packages\django\core\handlers\exception.py", line 35, in inner
    response = get_response(request)
  File "C:\Python36\lib\site-packages\django\core\handlers\base.py", line 139, in _get_response
    "returned None instead." % (callback.__module__, view_name)
ValueError: The view HttpRunnerManager.activator.process didn't return an HttpResponse object. It returned None instead.
2019-01-02 15:29:23,555 [django.request:118] [exception:handle_uncaught_exception] [ERROR]- Internal Server Error: /api/run_test_dubbo_module/
Traceback (most recent call last):
  File "C:\Python36\lib\site-packages\django\core\handlers\exception.py", line 35, in inner
    response = get_response(request)
  File "C:\Python36\lib\site-packages\django\core\handlers\base.py", line 139, in _get_response
    "returned None instead." % (callback.__module__, view_name)
ValueError: The view HttpRunnerManager.activator.process didn't return an HttpResponse object. It returned None instead.
2019-01-02 15:41:41,304 [HttpRunnerManager:56] [views:login] [INFO]- qianliguang 登录成功
2019-01-02 15:41:47,853 [django.request:118] [exception:handle_uncaught_exception] [ERROR]- Internal Server Error: /api/run_test_dubbo_module/
Traceback (most recent call last):
  File "C:\Python36\lib\site-packages\django\core\handlers\exception.py", line 35, in inner
    response = get_response(request)
  File "C:\Python36\lib\site-packages\django\core\handlers\base.py", line 128, in _get_response
    response = self.process_exception_by_middleware(e, request)
  File "C:\Python36\lib\site-packages\django\core\handlers\base.py", line 126, in _get_response
    response = wrapped_callback(request, *callback_args, **callback_kwargs)
  File "D:\jzs_workspace\projects\httprunnerm_test\HttpRunnerManager\activator.py", line 15, in process
    result = fun(request, index) if index else fun(request)
  File "D:\jzs_workspace\projects\httprunnerm_test\ApiManager\views.py", line 40, in wrapper
    return func(request, *args, **kwargs)
  File "D:\jzs_workspace\projects\httprunnerm_test\ApiManager\views.py", line 998, in run_test_dubbo_module
    idlist=get_cases_by_module(id)
  File "D:\jzs_workspace\projects\httprunnerm_test\ApiManager\utils\operation.py", line 464, in get_cases_by_module
    ids=case_opt.get_case_id_InModule(module_id)
  File "D:\jzs_workspace\projects\httprunnerm_test\ApiManager\managers.py", line 129, in get_case_id_InModule
    id_list.append(index[row])
TypeError: tuple indices must be integers or slices, not str
2019-01-02 15:42:20,923 [django.request:118] [exception:handle_uncaught_exception] [ERROR]- Internal Server Error: /api/run_test_dubbo_module/
Traceback (most recent call last):
  File "C:\Python36\lib\site-packages\django\core\handlers\exception.py", line 35, in inner
    response = get_response(request)
  File "C:\Python36\lib\site-packages\django\core\handlers\base.py", line 139, in _get_response
    "returned None instead." % (callback.__module__, view_name)
ValueError: The view HttpRunnerManager.activator.process didn't return an HttpResponse object. It returned None instead.
2019-01-11 17:15:39,780 [HttpRunnerManager:56] [views:login] [INFO]- qianliguang 登录成功
